Workbook

Sheet 計画入力
B1: 2027年 品種別 計画入力
B2: 計画原本｜黄色セルを入力・灰色セルは自動計算
B3: 入力は「入雛羽数・育成率・体重」の3表だけです。育成率は98%または0.98と入力してください。
B4: 未入力は空欄です。0は計画値0として扱います。重量はkg、体重はkg／羽で統一しています。
B6: 入雛羽数（羽） ［入力］
B7: 品種区分 | C7: 1月 | D7: 2月 | E7: 3月 | F7: 4月 | G7: 5月 | H7: 6月 | I7: 7月 | J7: 8月 | K7: 9月 | L7: 10月 | M7: 11月 | N7: 12月 | O7: 年計
B8: 阿波尾鶏 | O8: =IF(COUNT(C8:N8)<12,"",SUM(C8:N8))
B9: 赤どり | O9: =IF(COUNT(C9:N9)<12,"",SUM(C9:N9))
B10: 地養鳥 | O10: =IF(COUNT(C10:N10)<12,"",SUM(C10:N10))
B11: ブロイラー（貞光分） | O11: =IF(COUNT(C11:N11)<12,"",SUM(C11:N11))
B12: ブロイラー(外部購入) | O12: =IF(COUNT(C12:N12)<12,"",SUM(C12:N12))
B13: 合計 | C13: =IF(COUNT(C8:C12)<5,"",SUM(C8:C12)) | D13: =IF(COUNT(D8:D12)<5,"",SUM(D8:D12)) | E13: =IF(COUNT(E8:E12)<5,"",SUM(E8:E12)) | F13: =IF(COUNT(F8:F12)<5,"",SUM(F8:F12)) | G13: =IF(COUNT(G8:G12)<5,"",SUM(G8:G12)) | H13: =IF(COUNT(H8:H12)<5,"",SUM(H8:H12)) | I13: =IF(COUNT(I8:I12)<5,"",SUM(I8:I12)) | J13: =IF(COUNT(J8:J12)<5,"",SUM(J8:J12)) | ... O13: =IF(COUNT(O8:O12)<5,"",SUM(O8:O12))
B17: 処理羽数（羽） ［自動計算］
B18: 品種区分 | C18: 1月 | D18: 2月 | E18: 3月 | F18: 4月 | G18: 5月 | H18: 6月 | I18: 7月 | J18: 8月 | K18: 9月 | L18: 10月 | M18: 11月 | N18: 12月 | O18: 年計
B19: 阿波尾鶏 | C19: =IF(COUNT(C8,C41)<2,"",ROUND(C8*C41,0)) | D19: =IF(COUNT(D8,D41)<2,"",ROUND(D8*D41,0)) | E19: =IF(COUNT(E8,E41)<2,"",ROUND(E8*E41,0)) | F19: =IF(COUNT(F8,F41)<2,"",ROUND(F8*F41,0)) | G19: =IF(COUNT(G8,G41)<2,"",ROUND(G8*G41,0)) | H19: =IF(COUNT(H8,H41)<2,"",ROUND(H8*H41,0)) | I19: =IF(COUNT(I8,I41)<2,"",ROUND(I8*I41,0)) | J19: =IF(COUNT(J8,J41)<2,"",ROUND(J8*J41,0)) | ... N19: =IF(COUNT(N8,N41)<2,"",ROUND(N8*N41,0)) | O19: =IF(COUNT(C19:N19)<12,"",SUM(C19:N19))
B20: 赤どり | C20: =IF(COUNT(C9,C42)<2,"",ROUND(C9*C42,0)) | D20: =IF(COUNT(D9,D42)<2,"",ROUND(D9*D42,0)) | E20: =IF(COUNT(E9,E42)<2,"",ROUND(E9*E42,0)) | F20: =IF(COUNT(F9,F42)<2,"",ROUND(F9*F42,0)) | G20: =IF(COUNT(G9,G42)<2,"",ROUND(G9*G42,0)) | H20: =IF(COUNT(H9,H42)<2,"",ROUND(H9*H42,0)) | I20: =IF(COUNT(I9,I42)<2,"",ROUND(I9*I42,0)) | J20: =IF(COUNT(J9,J42)<2,"",ROUND(J9*J42,0)) | ... N20: =IF(COUNT(N9,N42)<2,"",ROUND(N9*N42,0)) | O20: =IF(COUNT(C20:N20)<12,"",SUM(C20:N20))
B21: 地養鳥 | C21: =IF(COUNT(C10,C43)<2,"",ROUND(C10*C43,0)) | D21: =IF(COUNT(D10,D43)<2,"",ROUND(D10*D43,0)) | E21: =IF(COUNT(E10,E43)<2,"",ROUND(E10*E43,0)) | F21: =IF(COUNT(F10,F43)<2,"",ROUND(F10*F43,0)) | G21: =IF(COUNT(G10,G43)<2,"",ROUND(G10*G43,0)) | H21: =IF(COUNT(H10,H43)<2,"",ROUND(H10*H43,0)) | I21: =IF(COUNT(I10,I43)<2,"",ROUND(I10*I43,0)) | J21: =IF(COUNT(J10,J43)<2,"",ROUND(J10*J43,0)) | ... N21: =IF(COUNT(N10,N43)<2,"",ROUND(N10*N43,0)) | O21: =IF(COUNT(C21:N21)<12,"",SUM(C21:N21))
B22: ブロイラー（貞光分） | C22: =IF(COUNT(C11,C44)<2,"",ROUND(C11*C44,0)) | D22: =IF(COUNT(D11,D44)<2,"",ROUND(D11*D44,0)) | E22: =IF(COUNT(E11,E44)<2,"",ROUND(E11*E44,0)) | F22: =IF(COUNT(F11,F44)<2,"",ROUND(F11*F44,0)) | G22: =IF(COUNT(G11,G44)<2,"",ROUND(G11*G44,0)) | H22: =IF(COUNT(H11,H44)<2,"",ROUND(H11*H44,0)) | I22: =IF(COUNT(I11,I44)<2,"",ROUND(I11*I44,0)) | J22: =IF(COUNT(J11,J44)<2,"",ROUND(J11*J44,0)) | ... N22: =IF(COUNT(N11,N44)<2,"",ROUND(N11*N44,0)) | O22: =IF(COUNT(C22:N22)<12,"",SUM(C22:N22))
B23: ブロイラー(外部購入) | C23: =IF(COUNT(C12,C45)<2,"",ROUND(C12*C45,0)) | D23: =IF(COUNT(D12,D45)<2,"",ROUND(D12*D45,0)) | E23: =IF(COUNT(E12,E45)<2,"",ROUND(E12*E45,0)) | F23: =IF(COUNT(F12,F45)<2,"",ROUND(F12*F45,0)) | G23: =IF(COUNT(G12,G45)<2,"",ROUND(G12*G45,0)) | H23: =IF(COUNT(H12,H45)<2,"",ROUND(H12*H45,0)) | I23: =IF(COUNT(I12,I45)<2,"",ROUND(I12*I45,0)) | J23: =IF(COUNT(J12,J45)<2,"",ROUND(J12*J45,0)) | ... N23: =IF(COUNT(N12,N45)<2,"",ROUND(N12*N45,0)) | O23: =IF(COUNT(C23:N23)<12,"",SUM(C23:N23))
B24: 合計 | C24: =IF(COUNT(C19:C23)<5,"",SUM(C19:C23)) | D24: =IF(COUNT(D19:D23)<5,"",SUM(D19:D23)) | E24: =IF(COUNT(E19:E23)<5,"",SUM(E19:E23)) | F24: =IF(COUNT(F19:F23)<5,"",SUM(F19:F23)) | G24: =IF(COUNT(G19:G23)<5,"",SUM(G19:G23)) | H24: =IF(COUNT(H19:H23)<5,"",SUM(H19:H23)) | I24: =IF(COUNT(I19:I23)<5,"",SUM(I19:I23)) | J24: =IF(COUNT(J19:J23)<5,"",SUM(J19:J23)) | ... O24: =IF(COUNT(O19:O23)<5,"",SUM(O19:O23))
B28: 処理重量（kg） ［自動計算］
B29: 品種区分 | C29: 1月 | D29: 2月 | E29: 3月 | F29: 4月 | G29: 5月 | H29: 6月 | I29: 7月 | J29: 8月 | K29: 9月 | L29: 10月 | M29: 11月 | N29: 12月 | O29: 年計
B30: 阿波尾鶏 | C30: =IF(COUNT(C19,C52)<2,"",ROUND(C19*C52,1)) | D30: =IF(COUNT(D19,D52)<2,"",ROUND(D19*D52,1)) | E30: =IF(COUNT(E19,E52)<2,"",ROUND(E19*E52,1)) | F30: =IF(COUNT(F19,F52)<2,"",ROUND(F19*F52,1)) | G30: =IF(COUNT(G19,G52)<2,"",ROUND(G19*G52,1)) | H30: =IF(COUNT(H19,H52)<2,"",ROUND(H19*H52,1)) | I30: =IF(COUNT(I19,I52)<2,"",ROUND(I19*I52,1)) | J30: =IF(COUNT(J19,J52)<2,"",ROUND(J19*J52,1)) | ... N30: =IF(COUNT(N19,N52)<2,"",ROUND(N19*N52,1)) | O30: =IF(COUNT(C30:N30)<12,"",SUM(C30:N30))
B31: 赤どり | C31: =IF(COUNT(C20,C53)<2,"",ROUND(C20*C53,1)) | D31: =IF(COUNT(D20,D53)<2,"",ROUND(D20*D53,1)) | E31: =IF(COUNT(E20,E53)<2,"",ROUND(E20*E53,1)) | F31: =IF(COUNT(F20,F53)<2,"",ROUND(F20*F53,1)) | G31: =IF(COUNT(G20,G53)<2,"",ROUND(G20*G53,1)) | H31: =IF(COUNT(H20,H53)<2,"",ROUND(H20*H53,1)) | I31: =IF(COUNT(I20,I53)<2,"",ROUND(I20*I53,1)) | J31: =IF(COUNT(J20,J53)<2,"",ROUND(J20*J53,1)) | ... N31: =IF(COUNT(N20,N53)<2,"",ROUND(N20*N53,1)) | O31: =IF(COUNT(C31:N31)<12,"",SUM(C31:N31))
B32: 地養鳥 | C32: =IF(COUNT(C21,C54)<2,"",ROUND(C21*C54,1)) | D32: =IF(COUNT(D21,D54)<2,"",ROUND(D21*D54,1)) | E32: =IF(COUNT(E21,E54)<2,"",ROUND(E21*E54,1)) | F32: =IF(COUNT(F21,F54)<2,"",ROUND(F21*F54,1)) | G32: =IF(COUNT(G21,G54)<2,"",ROUND(G21*G54,1)) | H32: =IF(COUNT(H21,H54)<2,"",ROUND(H21*H54,1)) | I32: =IF(COUNT(I21,I54)<2,"",ROUND(I21*I54,1)) | J32: =IF(COUNT(J21,J54)<2,"",ROUND(J21*J54,1)) | ... N32: =IF(COUNT(N21,N54)<2,"",ROUND(N21*N54,1)) | O32: =IF(COUNT(C32:N32)<12,"",SUM(C32:N32))
B33: ブロイラー（貞光分） | C33: =IF(COUNT(C22,C55)<2,"",ROUND(C22*C55,1)) | D33: =IF(COUNT(D22,D55)<2,"",ROUND(D22*D55,1)) | E33: =IF(COUNT(E22,E55)<2,"",ROUND(E22*E55,1)) | F33: =IF(COUNT(F22,F55)<2,"",ROUND(F22*F55,1)) | G33: =IF(COUNT(G22,G55)<2,"",ROUND(G22*G55,1)) | H33: =IF(COUNT(H22,H55)<2,"",ROUND(H22*H55,1)) | I33: =IF(COUNT(I22,I55)<2,"",ROUND(I22*I55,1)) | J33: =IF(COUNT(J22,J55)<2,"",ROUND(J22*J55,1)) | ... N33: =IF(COUNT(N22,N55)<2,"",ROUND(N22*N55,1)) | O33: =IF(COUNT(C33:N33)<12,"",SUM(C33:N33))
B34: ブロイラー(外部購入) | C34: =IF(COUNT(C23,C56)<2,"",ROUND(C23*C56,1)) | D34: =IF(COUNT(D23,D56)<2,"",ROUND(D23*D56,1)) | E34: =IF(COUNT(E23,E56)<2,"",ROUND(E23*E56,1)) | F34: =IF(COUNT(F23,F56)<2,"",ROUND(F23*F56,1)) | G34: =IF(COUNT(G23,G56)<2,"",ROUND(G23*G56,1)) | H34: =IF(COUNT(H23,H56)<2,"",ROUND(H23*H56,1)) | I34: =IF(COUNT(I23,I56)<2,"",ROUND(I23*I56,1)) | J34: =IF(COUNT(J23,J56)<2,"",ROUND(J23*J56,1)) | ... N34: =IF(COUNT(N23,N56)<2,"",ROUND(N23*N56,1)) | O34: =IF(COUNT(C34:N34)<12,"",SUM(C34:N34))
B35: 合計 | C35: =IF(COUNT(C30:C34)<5,"",SUM(C30:C34)) | D35: =IF(COUNT(D30:D34)<5,"",SUM(D30:D34)) | E35: =IF(COUNT(E30:E34)<5,"",SUM(E30:E34)) | F35: =IF(COUNT(F30:F34)<5,"",SUM(F30:F34)) | G35: =IF(COUNT(G30:G34)<5,"",SUM(G30:G34)) | H35: =IF(COUNT(H30:H34)<5,"",SUM(H30:H34)) | I35: =IF(COUNT(I30:I34)<5,"",SUM(I30:I34)) | J35: =IF(COUNT(J30:J34)<5,"",SUM(J30:J34)) | ... O35: =IF(COUNT(O30:O34)<5,"",SUM(O30:O34))
B39: 育成率 ［入力］
B40: 品種区分 | C40: 1月 | D40: 2月 | E40: 3月 | F40: 4月 | G40: 5月 | H40: 6月 | I40: 7月 | J40: 8月 | K40: 9月 | L40: 10月 | M40: 11月 | N40: 12月 | O40: 年間値
B41: 阿波尾鶏 | O41: =IF(COUNT(O19,O8)<2,"",IF(O8=0,"",O19/O8))
B42: 赤どり | O42: =IF(COUNT(O20,O9)<2,"",IF(O9=0,"",O20/O9))
B43: 地養鳥 | O43: =IF(COUNT(O21,O10)<2,"",IF(O10=0,"",O21/O10))
B44: ブロイラー（貞光分） | O44: =IF(COUNT(O22,O11)<2,"",IF(O11=0,"",O22/O11))
B45: ブロイラー(外部購入) | O45: =IF(COUNT(O23,O12)<2,"",IF(O12=0,"",O23/O12))
B46: 全体値（加重） | C46: =IF(COUNT(C24,C13)<2,"",IF(C13=0,"",C24/C13)) | D46: =IF(COUNT(D24,D13)<2,"",IF(D13=0,"",D24/D13)) | E46: =IF(COUNT(E24,E13)<2,"",IF(E13=0,"",E24/E13)) | F46: =IF(COUNT(F24,F13)<2,"",IF(F13=0,"",F24/F13)) | G46: =IF(COUNT(G24,G13)<2,"",IF(G13=0,"",G24/G13)) | H46: =IF(COUNT(H24,H13)<2,"",IF(H13=0,"",H24/H13)) | I46: =IF(COUNT(I24,I13)<2,"",IF(I13=0,"",I24/I13)) | J46: =IF(COUNT(J24,J13)<2,"",IF(J13=0,"",J24/J13)) | ... O46: =IF(COUNT(O24,O13)<2,"",IF(O13=0,"",O24/O13))
B50: 平均体重（kg／羽） ［入力］
B51: 品種区分 | C51: 1月 | D51: 2月 | E51: 3月 | F51: 4月 | G51: 5月 | H51: 6月 | I51: 7月 | J51: 8月 | K51: 9月 | L51: 10月 | M51: 11月 | N51: 12月 | O51: 年間値
B52: 阿波尾鶏 | O52: =IF(COUNT(O30,O19)<2,"",IF(O19=0,"",O30/O19))
B53: 赤どり | O53: =IF(COUNT(O31,O20)<2,"",IF(O20=0,"",O31/O20))
...

Sheet 前年実績
B1: 2026年 品種別 前年実績
B2: 参考データ｜実績の収録期間：2026年1～7月。8～12月は未収録
B3: 添付明細から集計した廃棄控除後の実績です。右端は1～7月累計で、年間確定値ではありません。
B4: 実績0と未収録を区別しています。入力セルはありません。実績データの更新は別途必要です。
B6: 入雛羽数（羽） ［参考実績］
B7: 品種区分 | C7: 1月 | D7: 2月 | E7: 3月 | F7: 4月 | G7: 5月 | H7: 6月 | I7: 7月 | J7: 8月 | K7: 9月 | L7: 10月 | M7: 11月 | N7: 12月 | O7: 1～7月累計
B8: 阿波尾鶏 | C8: 55006 | D8: 52673 | E8: 62600 | F8: 55850 | G8: 57139 | H8: 63100 | I8: 57800 | O8: =IF(COUNT(C8:N8)=0,"",SUM(C8:N8)) -> 404168
B9: 赤どり | C9: 90900 | D9: 86200 | E9: 78400 | F9: 79900 | G9: 69900 | H9: 49500 | I9: 75600 | O9: =IF(COUNT(C9:N9)=0,"",SUM(C9:N9)) -> 530400
B10: 地養鳥 | C10: 350600 | D10: 292400 | E10: 351200 | F10: 322300 | G10: 345100 | H10: 366900 | I10: 299800 | O10: =IF(COUNT(C10:N10)=0,"",SUM(C10:N10)) -> 2328300
B11: ブロイラー（貞光分） | C11: 214900 | D11: 229000 | E11: 219800 | F11: 251100 | G11: 240700 | H11: 224400 | I11: 232700 | O11: =IF(COUNT(C11:N11)=0,"",SUM(C11:N11)) -> 1612600
B12: ブロイラー(外部購入) | C12: 72000 | D12: 70212 | E12: 72000 | F12: 67200 | G12: 60000 | H12: 62403 | I12: 50000 | O12: =IF(COUNT(C12:N12)=0,"",SUM(C12:N12)) -> 453815
B13: 合計 | C13: =IF(COUNT(C8:C12)<5,"",SUM(C8:C12)) -> 783406 | D13: =IF(COUNT(D8:D12)<5,"",SUM(D8:D12)) -> 730485 | E13: =IF(COUNT(E8:E12)<5,"",SUM(E8:E12)) -> 784000 | F13: =IF(COUNT(F8:F12)<5,"",SUM(F8:F12)) -> 776350 | G13: =IF(COUNT(G8:G12)<5,"",SUM(G8:G12)) -> 772839 | H13: =IF(COUNT(H8:H12)<5,"",SUM(H8:H12)) -> 766303 | I13: =IF(COUNT(I8:I12)<5,"",SUM(I8:I12)) -> 715900 | J13: =IF(COUNT(J8:J12)<5,"",SUM(J8:J12)) | ... O13: =IF(COUNT(O8:O12)<5,"",SUM(O8:O12)) -> 5329283
B17: 処理羽数（羽） ［参考実績］
B18: 品種区分 | C18: 1月 | D18: 2月 | E18: 3月 | F18: 4月 | G18: 5月 | H18: 6月 | I18: 7月 | J18: 8月 | K18: 9月 | L18: 10月 | M18: 11月 | N18: 12月 | O18: 1～7月累計
B19: 阿波尾鶏 | C19: 49662 | D19: 49599 | E19: 61442 | F19: 54597 | G19: 56130 | H19: 62784 | I19: 56448 | O19: =IF(COUNT(C19:N19)=0,"",SUM(C19:N19)) -> 390662
B20: 赤どり | C20: 87323 | D20: 79427 | E20: 74827 | F20: 74076 | G20: 66268 | H20: 46813 | I20: 71538 | O20: =IF(COUNT(C20:N20)=0,"",SUM(C20:N20)) -> 500272
B21: 地養鳥 | C21: 341440 | D21: 285288 | E21: 338800 | F21: 316248 | G21: 336398 | H21: 359533 | I21: 295444 | O21: =IF(COUNT(C21:N21)=0,"",SUM(C21:N21)) -> 2273151
B22: ブロイラー（貞光分） | C22: 207713 | D22: 219312 | E22: 214270 | F22: 244140 | G22: 235820 | H22: 221305 | I22: 231256 | O22: =IF(COUNT(C22:N22)=0,"",SUM(C22:N22)) -> 1573816
B23: ブロイラー(外部購入) | C23: 70038 | D23: 67166 | E23: 70082 | F23: 66276 | G23: 59008 | H23: 61497 | I23: 49445 | O23: =IF(COUNT(C23:N23)=0,"",SUM(C23:N23)) -> 443512
B24: 合計 | C24: =IF(COUNT(C19:C23)<5,"",SUM(C19:C23)) -> 756176 | D24: =IF(COUNT(D19:D23)<5,"",SUM(D19:D23)) -> 700792 | E24: =IF(COUNT(E19:E23)<5,"",SUM(E19:E23)) -> 759421 | F24: =IF(COUNT(F19:F23)<5,"",SUM(F19:F23)) -> 755337 | G24: =IF(COUNT(G19:G23)<5,"",SUM(G19:G23)) -> 753624 | H24: =IF(COUNT(H19:H23)<5,"",SUM(H19:H23)) -> 751932 | I24: =IF(COUNT(I19:I23)<5,"",SUM(I19:I23)) -> 704131 | J24: =IF(COUNT(J19:J23)<5,"",SUM(J19:J23)) | ... O24: =IF(COUNT(O19:O23)<5,"",SUM(O19:O23)) -> 5181413
B28: 処理重量（kg） ［参考実績］
B29: 品種区分 | C29: 1月 | D29: 2月 | E29: 3月 | F29: 4月 | G29: 5月 | H29: 6月 | I29: 7月 | J29: 8月 | K29: 9月 | L29: 10月 | M29: 11月 | N29: 12月 | O29: 1～7月累計
B30: 阿波尾鶏 | C30: 187405.1 | D30: 181907.4 | E30: 231200.2 | F30: 197733.5 | G30: 196536.9 | H30: 221566.7 | I30: 194013.4 | O30: =IF(COUNT(C30:N30)=0,"",SUM(C30:N30)) -> 1410363.2
B31: 赤どり | C31: 286299.4 | D31: 251579.7 | E31: 246681.9 | F31: 251832.3 | G31: 213503.4 | H31: 156492.9 | I31: 238821.8 | O31: =IF(COUNT(C31:N31)=0,"",SUM(C31:N31)) -> 1645211.4
B32: 地養鳥 | C32: 985452.8 | D32: 834735.6 | E32: 998232.7 | F32: 968720.2 | G32: 1042549.9 | H32: 1125852 | I32: 891736.9 | O32: =IF(COUNT(C32:N32)=0,"",SUM(C32:N32)) -> 6847280.1
B33: ブロイラー（貞光分） | C33: 653184.1 | D33: 687485 | E33: 703985.5 | F33: 796245.3 | G33: 769508.9 | H33: 716889.8 | I33: 725315.1 | O33: =IF(COUNT(C33:N33)=0,"",SUM(C33:N33)) -> 5052613.7
B34: ブロイラー(外部購入) | C34: 224870.9 | D34: 219172.2 | E34: 233382 | F34: 214726.2 | G34: 194159.9 | H34: 204679.6 | I34: 155893.7 | O34: =IF(COUNT(C34:N34)=0,"",SUM(C34:N34)) -> 1446884.5
B35: 合計 | C35: =IF(COUNT(C30:C34)<5,"",SUM(C30:C34)) -> 2337212.3 | D35: =IF(COUNT(D30:D34)<5,"",SUM(D30:D34)) -> 2174879.9 | E35: =IF(COUNT(E30:E34)<5,"",SUM(E30:E34)) -> 2413482.3 | F35: =IF(COUNT(F30:F34)<5,"",SUM(F30:F34)) -> 2429257.5 | G35: =IF(COUNT(G30:G34)<5,"",SUM(G30:G34)) -> 2416259 | H35: =IF(COUNT(H30:H34)<5,"",SUM(H30:H34)) -> 2425481 | I35: =IF(COUNT(I30:I34)<5,"",SUM(I30:I34)) -> 2205780.9 | J35: =IF(COUNT(J30:J34)<5,"",SUM(J30:J34)) | ... O35: =IF(COUNT(O30:O34)<5,"",SUM(O30:O34)) -> 16402353
B39: 育成率 ［参考実績］
B40: 品種区分 | C40: 1月 | D40: 2月 | E40: 3月 | F40: 4月 | G40: 5月 | H40: 6月 | I40: 7月 | J40: 8月 | K40: 9月 | L40: 10月 | M40: 11月 | N40: 12月 | O40: 1～7月通期率
B41: 阿波尾鶏 | C41: =IF(COUNT(C19,C8)<2,"",IF(C8=0,"",C19/C8)) -> 0.90284696 | D41: =IF(COUNT(D19,D8)<2,"",IF(D8=0,"",D19/D8)) -> 0.94163993 | E41: =IF(COUNT(E19,E8)<2,"",IF(E8=0,"",E19/E8)) -> 0.9815016 | F41: =IF(COUNT(F19,F8)<2,"",IF(F8=0,"",F19/F8)) -> 0.97756491 | G41: =IF(COUNT(G19,G8)<2,"",IF(G8=0,"",G19/G8)) -> 0.98234131 | H41: =IF(COUNT(H19,H8)<2,"",IF(H8=0,"",H19/H8)) -> 0.99499208 | I41: =IF(COUNT(I19,I8)<2,"",IF(I8=0,"",I19/I8)) -> 0.976609 | J41: =IF(COUNT(J19,J8)<2,"",IF(J8=0,"",J19/J8)) | ... O41: =IF(COUNT(O19,O8)<2,"",IF(O8=0,"",O19/O8)) -> 0.9665832
B42: 赤どり | C42: =IF(COUNT(C20,C9)<2,"",IF(C9=0,"",C20/C9)) -> 0.96064906 | D42: =IF(COUNT(D20,D9)<2,"",IF(D9=0,"",D20/D9)) -> 0.92142691 | E42: =IF(COUNT(E20,E9)<2,"",IF(E9=0,"",E20/E9)) -> 0.95442602 | F42: =IF(COUNT(F20,F9)<2,"",IF(F9=0,"",F20/F9)) -> 0.92710889 | G42: =IF(COUNT(G20,G9)<2,"",IF(G9=0,"",G20/G9)) -> 0.94804006 | H42: =IF(COUNT(H20,H9)<2,"",IF(H9=0,"",H20/H9)) -> 0.94571717 | I42: =IF(COUNT(I20,I9)<2,"",IF(I9=0,"",I20/I9)) -> 0.94626984 | J42: =IF(COUNT(J20,J9)<2,"",IF(J9=0,"",J20/J9)) | ... O42: =IF(COUNT(O20,O9)<2,"",IF(O9=0,"",O20/O9)) -> 0.94319759
B43: 地養鳥 | C43: =IF(COUNT(C21,C10)<2,"",IF(C10=0,"",C21/C10)) -> 0.97387336 | D43: =IF(COUNT(D21,D10)<2,"",IF(D10=0,"",D21/D10)) -> 0.97567715 | E43: =IF(COUNT(E21,E10)<2,"",IF(E10=0,"",E21/E10)) -> 0.96469248 | F43: =IF(COUNT(F21,F10)<2,"",IF(F10=0,"",F21/F10)) -> 0.98122246 | G43: =IF(COUNT(G21,G10)<2,"",IF(G10=0,"",G21/G10)) -> 0.97478412 | H43: =IF(COUNT(H21,H10)<2,"",IF(H10=0,"",H21/H10)) -> 0.97992096 | I43: =IF(COUNT(I21,I10)<2,"",IF(I10=0,"",I21/I10)) -> 0.98547031 | J43: =IF(COUNT(J21,J10)<2,"",IF(J10=0,"",J21/J10)) | ... O43: =IF(COUNT(O21,O10)<2,"",IF(O10=0,"",O21/O10)) -> 0.97631362
B44: ブロイラー（貞光分） | C44: =IF(COUNT(C22,C11)<2,"",IF(C11=0,"",C22/C11)) -> 0.96655654 | D44: =IF(COUNT(D22,D11)<2,"",IF(D11=0,"",D22/D11)) -> 0.95769432 | E44: =IF(COUNT(E22,E11)<2,"",IF(E11=0,"",E22/E11)) -> 0.97484076 | F44: =IF(COUNT(F22,F11)<2,"",IF(F11=0,"",F22/F11)) -> 0.97228196 | G44: =IF(COUNT(G22,G11)<2,"",IF(G11=0,"",G22/G11)) -> 0.9797258 | H44: =IF(COUNT(H22,H11)<2,"",IF(H11=0,"",H22/H11)) -> 0.98620766 | I44: =IF(COUNT(I22,I11)<2,"",IF(I11=0,"",I22/I11)) -> 0.99379459 | J44: =IF(COUNT(J22,J11)<2,"",IF(J11=0,"",J22/J11)) | ... O44: =IF(COUNT(O22,O11)<2,"",IF(O11=0,"",O22/O11)) -> 0.9759494
B45: ブロイラー(外部購入) | C45: =IF(COUNT(C23,C12)<2,"",IF(C12=0,"",C23/C12)) -> 0.97275 | D45: =IF(COUNT(D23,D12)<2,"",IF(D12=0,"",D23/D12)) -> 0.9566171 | E45: =IF(COUNT(E23,E12)<2,"",IF(E12=0,"",E23/E12)) -> 0.97336111 | F45: =IF(COUNT(F23,F12)<2,"",IF(F12=0,"",F23/F12)) -> 0.98625 | G45: =IF(COUNT(G23,G12)<2,"",IF(G12=0,"",G23/G12)) -> 0.98346667 | H45: =IF(COUNT(H23,H12)<2,"",IF(H12=0,"",H23/H12)) -> 0.98548147 | I45: =IF(COUNT(I23,I12)<2,"",IF(I12=0,"",I23/I12)) -> 0.9889 | J45: =IF(COUNT(J23,J12)<2,"",IF(J12=0,"",J23/J12)) | ... O45: =IF(COUNT(O23,O12)<2,"",IF(O12=0,"",O23/O12)) -> 0.97729692
B46: 全体値（加重） | C46: =IF(COUNT(C24,C13)<2,"",IF(C13=0,"",C24/C13)) -> 0.96524152 | D46: =IF(COUNT(D24,D13)<2,"",IF(D13=0,"",D24/D13)) -> 0.95935166 | E46: =IF(COUNT(E24,E13)<2,"",IF(E13=0,"",E24/E13)) -> 0.96864923 | F46: =IF(COUNT(F24,F13)<2,"",IF(F13=0,"",F24/F13)) -> 0.9729336 | G46: =IF(COUNT(G24,G13)<2,"",IF(G13=0,"",G24/G13)) -> 0.97513712 | H46: =IF(COUNT(H24,H13)<2,"",IF(H13=0,"",H24/H13)) -> 0.98124632 | I46: =IF(COUNT(I24,I13)<2,"",IF(I13=0,"",I24/I13)) -> 0.98356055 | J46: =IF(COUNT(J24,J13)<2,"",IF(J13=0,"",J24/J13)) | ... O46: =IF(COUNT(O24,O13)<2,"",IF(O13=0,"",O24/O13)) -> 0.9722533
B50: 平均体重（kg／羽） ［参考実績］
B51: 品種区分 | C51: 1月 | D51: 2月 | E51: 3月 | F51: 4月 | G51: 5月 | H51: 6月 | I51: 7月 | J51: 8月 | K51: 9月 | L51: 10月 | M51: 11月 | N51: 12月 | O51: 1～7月通期体重
B52: 阿波尾鶏 | C52: =IF(COUNT(C30,C19)<2,"",IF(C19=0,"",C30/C19)) -> 3.7736116 | D52: =IF(COUNT(D30,D19)<2,"",IF(D19=0,"",D30/D19)) -> 3.6675618 | E52: =IF(COUNT(E30,E19)<2,"",IF(E19=0,"",E30/E19)) -> 3.7629016 | F52: =IF(COUNT(F30,F19)<2,"",IF(F19=0,"",F30/F19)) -> 3.6216917 | G52: =IF(COUNT(G30,G19)<2,"",IF(G19=0,"",G30/G19)) -> 3.5014591 | H52: =IF(COUNT(H30,H19)<2,"",IF(H19=0,"",H30/H19)) -> 3.5290313 | I52: =IF(COUNT(I30,I19)<2,"",IF(I19=0,"",I30/I19)) -> 3.4370288 | J52: =IF(COUNT(J30,J19)<2,"",IF(J19=0,"",J30/J19)) | ... O52: =IF(COUNT(O30,O19)<2,"",IF(O19=0,"",O30/O19)) -> 3.6101878
B53: 赤どり | C53: =IF(COUNT(C31,C20)<2,"",IF(C20=0,"",C31/C20)) -> 3.2786253 | D53: =IF(COUNT(D31,D20)<2,"",IF(D20=0,"",D31/D20)) -> 3.167433 | E53: =IF(COUNT(E31,E20)<2,"",IF(E20=0,"",E31/E20)) -> 3.2966964 | F53: =IF(COUNT(F31,F20)<2,"",IF(F20=0,"",F31/F20)) -> 3.3996477 | G53: =IF(COUNT(G31,G20)<2,"",IF(G20=0,"",G31/G20)) -> 3.2218175 | H53: =IF(COUNT(H31,H20)<2,"",IF(H20=0,"",H31/H20)) -> 3.3429368 | I53: =IF(COUNT(I31,I20)<2,"",IF(I20=0,"",I31/I20)) -> 3.3383908 | J53: =IF(COUNT(J31,J20)<2,"",IF(J20=0,"",J31/J20)) | ... O53: =IF(COUNT(O31,O20)<2,"",IF(O20=0,"",O31/O20)) -> 3.2886338
...

Sheet 計画確認
B1: 2027年 計画確認
B2: 入力チェック・年間計画・前年同期間との比較
B3: 計画原本の入力状況を確認します。入力欄はありません。年間値は12か月分の入力がそろうと表示します。
B4: 前年比較は前年実績がある1～7月に期間をそろえます。2027年の実績や実績対比表は、このブックには含みません。
B6: 1 入力チェック（1品種36セル・全体180セル）
B7: 品種区分 | C7: 入力済み | D7: 未入力 | E7: 状態
B8: 阿波尾鶏 | C8: =COUNT('計画入力'!C8:N8,'計画入力'!C41:N41,'計画入力'!C52:N52) -> 0 | D8: =36-C8 -> 36 | E8: =IF(D8=0,"入力完了","未入力あり") -> 未入力あり
B9: 赤どり | C9: =COUNT('計画入力'!C9:N9,'計画入力'!C42:N42,'計画入力'!C53:N53) -> 0 | D9: =36-C9 -> 36 | E9: =IF(D9=0,"入力完了","未入力あり") -> 未入力あり
B10: 地養鳥 | C10: =COUNT('計画入力'!C10:N10,'計画入力'!C43:N43,'計画入力'!C54:N54) -> 0 | D10: =36-C10 -> 36 | E10: =IF(D10=0,"入力完了","未入力あり") -> 未入力あり
B11: ブロイラー（貞光分） | C11: =COUNT('計画入力'!C11:N11,'計画入力'!C44:N44,'計画入力'!C55:N55) -> 0 | D11: =36-C11 -> 36 | E11: =IF(D11=0,"入力完了","未入力あり") -> 未入力あり
B12: ブロイラー(外部購入) | C12: =COUNT('計画入力'!C12:N12,'計画入力'!C45:N45,'計画入力'!C56:N56) -> 0 | D12: =36-C12 -> 36 | E12: =IF(D12=0,"入力完了","未入力あり") -> 未入力あり
B13: 全体 | C13: =SUM(C8:C12) -> 0 | D13: =SUM(D8:D12) -> 180 | E13: =IF(D13=0,"入力完了","未入力あり") -> 未入力あり
B16: 2 年間計画の確認（入力がそろうまで空欄）
B17: 品種区分 | C17: 入雛羽数 | D17: 処理羽数 | E17: 処理重量kg | F17: 育成率 | G17: 平均体重kg
B18: 阿波尾鶏 | C18: =IF(ISNUMBER('計画入力'!O8),'計画入力'!O8,"") | D18: =IF(ISNUMBER('計画入力'!O19),'計画入力'!O19,"") | E18: =IF(ISNUMBER('計画入力'!O30),'計画入力'!O30,"") | F18: =IF(ISNUMBER('計画入力'!O41),'計画入力'!O41,"") | G18: =IF(ISNUMBER('計画入力'!O52),'計画入力'!O52,"")
B19: 赤どり | C19: =IF(ISNUMBER('計画入力'!O9),'計画入力'!O9,"") | D19: =IF(ISNUMBER('計画入力'!O20),'計画入力'!O20,"") | E19: =IF(ISNUMBER('計画入力'!O31),'計画入力'!O31,"") | F19: =IF(ISNUMBER('計画入力'!O42),'計画入力'!O42,"") | G19: =IF(ISNUMBER('計画入力'!O53),'計画入力'!O53,"")
B20: 地養鳥 | C20: =IF(ISNUMBER('計画入力'!O10),'計画入力'!O10,"") | D20: =IF(ISNUMBER('計画入力'!O21),'計画入力'!O21,"") | E20: =IF(ISNUMBER('計画入力'!O32),'計画入力'!O32,"") | F20: =IF(ISNUMBER('計画入力'!O43),'計画入力'!O43,"") | G20: =IF(ISNUMBER('計画入力'!O54),'計画入力'!O54,"")
B21: ブロイラー（貞光分） | C21: =IF(ISNUMBER('計画入力'!O11),'計画入力'!O11,"") | D21: =IF(ISNUMBER('計画入力'!O22),'計画入力'!O22,"") | E21: =IF(ISNUMBER('計画入力'!O33),'計画入力'!O33,"") | F21: =IF(ISNUMBER('計画入力'!O44),'計画入力'!O44,"") | G21: =IF(ISNUMBER('計画入力'!O55),'計画入力'!O55,"")
B22: ブロイラー(外部購入) | C22: =IF(ISNUMBER('計画入力'!O12),'計画入力'!O12,"") | D22: =IF(ISNUMBER('計画入力'!O23),'計画入力'!O23,"") | E22: =IF(ISNUMBER('計画入力'!O34),'計画入力'!O34,"") | F22: =IF(ISNUMBER('計画入力'!O45),'計画入力'!O45,"") | G22: =IF(ISNUMBER('計画入力'!O56),'計画入力'!O56,"")
B25: 3 前年実績との同期間比較（1～7月・差引＝計画－前年実績）
B26: 品種区分 | C26: 計画入雛 1～7月 | D26: 前年入雛 1～7月 | E26: 差引（羽） | F26: 増減率 | G26: 計画処理 1～7月 | H26: 前年処理 1～7月 | I26: 差引（羽） | J26: 増減率 | K26: 計画重量kg 1～7月 | L26: 前年重量kg 1～7月 | M26: 差引（kg） | N26: 増減率 | O26: 確認状態
B27: 阿波尾鶏 | C27: =IF(COUNT('計画入力'!C8:I8)<7,"",SUM('計画入力'!C8:I8)) | D27: =SUM('前年実績'!C8:I8) -> 404168 | E27: =IF(COUNT(C27,D27)<2,"",C27-D27) | F27: =IF(COUNT(C27,D27)<2,"",IF(D27=0,"",E27/D27)) | G27: =IF(COUNT('計画入力'!C19:I19)<7,"",SUM('計画入力'!C19:I19)) | H27: =SUM('前年実績'!C19:I19) -> 390662 | I27: =IF(COUNT(G27,H27)<2,"",G27-H27) | J27: =IF(COUNT(G27,H27)<2,"",IF(H27=0,"",I27/H27)) | K27: =IF(COUNT('計画入力'!C30:I30)<7,"",SUM('計画入力'!C30:I30)) | L27: =SUM('前年実績'!C30:I30) -> 1410363.2 | M27: =IF(COUNT(K27,L27)<2,"",K27-L27) | N27: =IF(COUNT(K27,L27)<2,"",IF(L27=0,"",M27/L27)) | O27: =IF(COUNT(C27,G27,K27)=3,"比較可能","計画入力待ち") -> 計画入力待ち
B28: 赤どり | C28: =IF(COUNT('計画入力'!C9:I9)<7,"",SUM('計画入力'!C9:I9)) | D28: =SUM('前年実績'!C9:I9) -> 530400 | E28: =IF(COUNT(C28,D28)<2,"",C28-D28) | F28: =IF(COUNT(C28,D28)<2,"",IF(D28=0,"",E28/D28)) | G28: =IF(COUNT('計画入力'!C20:I20)<7,"",SUM('計画入力'!C20:I20)) | H28: =SUM('前年実績'!C20:I20) -> 500272 | I28: =IF(COUNT(G28,H28)<2,"",G28-H28) | J28: =IF(COUNT(G28,H28)<2,"",IF(H28=0,"",I28/H28)) | K28: =IF(COUNT('計画入力'!C31:I31)<7,"",SUM('計画入力'!C31:I31)) | L28: =SUM('前年実績'!C31:I31) -> 1645211.4 | M28: =IF(COUNT(K28,L28)<2,"",K28-L28) | N28: =IF(COUNT(K28,L28)<2,"",IF(L28=0,"",M28/L28)) | O28: =IF(COUNT(C28,G28,K28)=3,"比較可能","計画入力待ち") -> 計画入力待ち
B29: 地養鳥 | C29: =IF(COUNT('計画入力'!C10:I10)<7,"",SUM('計画入力'!C10:I10)) | D29: =SUM('前年実績'!C10:I10) -> 2328300 | E29: =IF(COUNT(C29,D29)<2,"",C29-D29) | F29: =IF(COUNT(C29,D29)<2,"",IF(D29=0,"",E29/D29)) | G29: =IF(COUNT('計画入力'!C21:I21)<7,"",SUM('計画入力'!C21:I21)) | H29: =SUM('前年実績'!C21:I21) -> 2273151 | I29: =IF(COUNT(G29,H29)<2,"",G29-H29) | J29: =IF(COUNT(G29,H29)<2,"",IF(H29=0,"",I29/H29)) | K29: =IF(COUNT('計画入力'!C32:I32)<7,"",SUM('計画入力'!C32:I32)) | L29: =SUM('前年実績'!C32:I32) -> 6847280.1 | M29: =IF(COUNT(K29,L29)<2,"",K29-L29) | N29: =IF(COUNT(K29,L29)<2,"",IF(L29=0,"",M29/L29)) | O29: =IF(COUNT(C29,G29,K29)=3,"比較可能","計画入力待ち") -> 計画入力待ち
B30: ブロイラー（貞光分） | C30: =IF(COUNT('計画入力'!C11:I11)<7,"",SUM('計画入力'!C11:I11)) | D30: =SUM('前年実績'!C11:I11) -> 1612600 | E30: =IF(COUNT(C30,D30)<2,"",C30-D30) | F30: =IF(COUNT(C30,D30)<2,"",IF(D30=0,"",E30/D30)) | G30: =IF(COUNT('計画入力'!C22:I22)<7,"",SUM('計画入力'!C22:I22)) | H30: =SUM('前年実績'!C22:I22) -> 1573816 | I30: =IF(COUNT(G30,H30)<2,"",G30-H30) | J30: =IF(COUNT(G30,H30)<2,"",IF(H30=0,"",I30/H30)) | K30: =IF(COUNT('計画入力'!C33:I33)<7,"",SUM('計画入力'!C33:I33)) | L30: =SUM('前年実績'!C33:I33) -> 5052613.7 | M30: =IF(COUNT(K30,L30)<2,"",K30-L30) | N30: =IF(COUNT(K30,L30)<2,"",IF(L30=0,"",M30/L30)) | O30: =IF(COUNT(C30,G30,K30)=3,"比較可能","計画入力待ち") -> 計画入力待ち
B31: ブロイラー(外部購入) | C31: =IF(COUNT('計画入力'!C12:I12)<7,"",SUM('計画入力'!C12:I12)) | D31: =SUM('前年実績'!C12:I12) -> 453815 | E31: =IF(COUNT(C31,D31)<2,"",C31-D31) | F31: =IF(COUNT(C31,D31)<2,"",IF(D31=0,"",E31/D31)) | G31: =IF(COUNT('計画入力'!C23:I23)<7,"",SUM('計画入力'!C23:I23)) | H31: =SUM('前年実績'!C23:I23) -> 443512 | I31: =IF(COUNT(G31,H31)<2,"",G31-H31) | J31: =IF(COUNT(G31,H31)<2,"",IF(H31=0,"",I31/H31)) | K31: =IF(COUNT('計画入力'!C34:I34)<7,"",SUM('計画入力'!C34:I34)) | L31: =SUM('前年実績'!C34:I34) -> 1446884.5 | M31: =IF(COUNT(K31,L31)<2,"",K31-L31) | N31: =IF(COUNT(K31,L31)<2,"",IF(L31=0,"",M31/L31)) | O31: =IF(COUNT(C31,G31,K31)=3,"比較可能","計画入力待ち") -> 計画入力待ち
B34: 使い方：①計画入力の黄色セルを入力 ②未入力数を確認 ③年間計画と前年同期間との差を確認 ④別名で保管。
B35: このExcelは計画入力用です。TSVの自動生成・実績対比表の作成プログラムやマクロは含みません。
B36: 体重・育成率の全体値は単純平均ではありません。計画と実績の対象期間・単位をそろえて比較してください。
